(0.001)
            SELECT name, type FROM sqlite_master
            WHERE type in ('table', 'view') AND NOT name='sqlite_sequence'
            ORDER BY name; args=None
(0.000) SELECT "django_migrations"."app", "django_migrations"."name" FROM "django_migrations"; args=()
(0.001) SELECT "django_session"."session_key", "django_session"."session_data", "django_session"."expire_date" FROM "django_session" WHERE ("django_session"."expire_date" > '2017-03-20 12:13:31.511588' AND "django_session"."session_key" = 'o6eyvii97s2jm9ym4ajtdtpv3v3vizs5'); args=('2017-03-20 12:13:31.511588', 'o6eyvii97s2jm9ym4ajtdtpv3v3vizs5')
(0.001) SELECT "auth_user"."id", "auth_user"."password", "auth_user"."last_login", "auth_user"."is_superuser", "auth_user"."username", "auth_user"."first_name", "auth_user"."last_name", "auth_user"."email", "auth_user"."is_staff", "auth_user"."is_active", "auth_user"."date_joined" FROM "auth_user" WHERE "auth_user"."id" = 1; args=(1,)
"GET /home/ HTTP/1.1" 200 3330
Exception while resolving variable 'name' in template 'unknown'.
Traceback (most recent call last):
  File "C:\Users\GS-1436\VE-1\lib\site-packages\django\core\handlers\exception.py", line 42, in inner
    response = get_response(request)
  File "C:\Users\GS-1436\VE-1\lib\site-packages\django\core\handlers\base.py", line 172, in _get_response
    resolver_match = resolver.resolve(request.path_info)
  File "C:\Users\GS-1436\VE-1\lib\site-packages\django\urls\resolvers.py", line 300, in resolve
    raise Resolver404({'tried': tried, 'path': new_path})
django.urls.exceptions.Resolver404: {'path': 'home/bgimg.jpg', 'tried': [[<RegexURLResolver <RegexURLPattern list> (admin:admin) ^admin/>], [<RegexURLResolver <module 'snapp.urls' from 'C:\\Users\\GS-1436\\PycharmProjects\\inductproject\\snapp\\urls.py'> (None:None) >, <RegexURLPattern home ^$>], [<RegexURLResolver <module 'snapp.urls' from 'C:\\Users\\GS-1436\\PycharmProjects\\inductproject\\snapp\\urls.py'> (None:None) >, <RegexURLPattern homepage ^home/$>], [<RegexURLResolver <module 'snapp.urls' from 'C:\\Users\\GS-1436\\PycharmProjects\\inductproject\\snapp\\urls.py'> (None:None) >, <RegexURLPattern list ^list/$>], [<RegexURLResolver <module 'snapp.urls' from 'C:\\Users\\GS-1436\\PycharmProjects\\inductproject\\snapp\\urls.py'> (None:None) >, <RegexURLPattern incident_details ^incident_details/(?P<sys_id>[A-Za-z0-9_@./&+-]+)$>], [<RegexURLResolver <module 'snapp.urls' from 'C:\\Users\\GS-1436\\PycharmProjects\\inductproject\\snapp\\urls.py'> (None:None) >, <RegexURLPattern createinc ^create/$>], [<RegexURLResolver <module 'snapp.urls' from 'C:\\Users\\GS-1436\\PycharmProjects\\inductproject\\snapp\\urls.py'> (None:None) >, <RegexURLPattern createdinc ^createdinc/$>], [<RegexURLResolver <module 'snapp.urls' from 'C:\\Users\\GS-1436\\PycharmProjects\\inductproject\\snapp\\urls.py'> (None:None) >, <RegexURLPattern updateinc ^update/$>], [<RegexURLResolver <module 'snapp.urls' from 'C:\\Users\\GS-1436\\PycharmProjects\\inductproject\\snapp\\urls.py'> (None:None) >, <RegexURLPattern update_select ^update_select/(?P<number>[A-Za-z0-9_@./&+-]+)$>], [<RegexURLResolver <module 'snapp.urls' from 'C:\\Users\\GS-1436\\PycharmProjects\\inductproject\\snapp\\urls.py'> (None:None) >, <RegexURLPattern getUpdateDetail ^getUpdateDetail/$>], [<RegexURLResolver <module 'snapp.urls' from 'C:\\Users\\GS-1436\\PycharmProjects\\inductproject\\snapp\\urls.py'> (None:None) >, <RegexURLPattern deleteinc ^delete/$>], [<RegexURLResolver <module 'snapp.urls' from 'C:\\Users\\GS-1436\\PycharmProjects\\inductproject\\snapp\\urls.py'> (None:None) >, <RegexURLPattern delete_select ^delete_select/$>], [<RegexURLPattern login ^login/$>], [<RegexURLPattern logout ^logout/$>]]}

During handling of the above exception, another exception occurred:

Traceback (most recent call last):
  File "C:\Users\GS-1436\VE-1\lib\site-packages\django\template\base.py", line 885, in _resolve_lookup
    current = current[bit]
TypeError: 'RegexURLResolver' object is not subscriptable

During handling of the above exception, another exception occurred:

Traceback (most recent call last):
  File "C:\Users\GS-1436\VE-1\lib\site-packages\django\template\base.py", line 893, in _resolve_lookup
    current = getattr(current, bit)
AttributeError: 'RegexURLResolver' object has no attribute 'name'

During handling of the above exception, another exception occurred:

Traceback (most recent call last):
  File "C:\Users\GS-1436\VE-1\lib\site-packages\django\template\base.py", line 900, in _resolve_lookup
    current = current[int(bit)]
ValueError: invalid literal for int() with base 10: 'name'

During handling of the above exception, another exception occurred:

Traceback (most recent call last):
  File "C:\Users\GS-1436\VE-1\lib\site-packages\django\template\base.py", line 907, in _resolve_lookup
    (bit, current))  # missing attribute
django.template.base.VariableDoesNotExist: Failed lookup for key [name] in '<RegexURLResolver <RegexURLPattern list> (admin:admin) ^admin/>'
Not Found: /home/bgimg.jpg
"GET /home/bgimg.jpg HTTP/1.1" 404 4231
(0.001) SELECT "django_session"."session_key", "django_session"."session_data", "django_session"."expire_date" FROM "django_session" WHERE ("django_session"."expire_date" > '2017-03-20 12:13:32.976735' AND "django_session"."session_key" = 'o6eyvii97s2jm9ym4ajtdtpv3v3vizs5'); args=('2017-03-20 12:13:32.976735', 'o6eyvii97s2jm9ym4ajtdtpv3v3vizs5')
(0.000) SELECT "auth_user"."id", "auth_user"."password", "auth_user"."last_login", "auth_user"."is_superuser", "auth_user"."username", "auth_user"."first_name", "auth_user"."last_name", "auth_user"."email", "auth_user"."is_staff", "auth_user"."is_active", "auth_user"."date_joined" FROM "auth_user" WHERE "auth_user"."id" = 1; args=(1,)
"GET /list/ HTTP/1.1" 200 30553
Exception while resolving variable 'name' in template 'unknown'.
Traceback (most recent call last):
  File "C:\Users\GS-1436\VE-1\lib\site-packages\django\core\handlers\exception.py", line 42, in inner
    response = get_response(request)
  File "C:\Users\GS-1436\VE-1\lib\site-packages\django\core\handlers\base.py", line 172, in _get_response
    resolver_match = resolver.resolve(request.path_info)
  File "C:\Users\GS-1436\VE-1\lib\site-packages\django\urls\resolvers.py", line 300, in resolve
    raise Resolver404({'tried': tried, 'path': new_path})
django.urls.exceptions.Resolver404: {'path': 'list/bgimg.jpg', 'tried': [[<RegexURLResolver <RegexURLPattern list> (admin:admin) ^admin/>], [<RegexURLResolver <module 'snapp.urls' from 'C:\\Users\\GS-1436\\PycharmProjects\\inductproject\\snapp\\urls.py'> (None:None) >, <RegexURLPattern home ^$>], [<RegexURLResolver <module 'snapp.urls' from 'C:\\Users\\GS-1436\\PycharmProjects\\inductproject\\snapp\\urls.py'> (None:None) >, <RegexURLPattern homepage ^home/$>], [<RegexURLResolver <module 'snapp.urls' from 'C:\\Users\\GS-1436\\PycharmProjects\\inductproject\\snapp\\urls.py'> (None:None) >, <RegexURLPattern list ^list/$>], [<RegexURLResolver <module 'snapp.urls' from 'C:\\Users\\GS-1436\\PycharmProjects\\inductproject\\snapp\\urls.py'> (None:None) >, <RegexURLPattern incident_details ^incident_details/(?P<sys_id>[A-Za-z0-9_@./&+-]+)$>], [<RegexURLResolver <module 'snapp.urls' from 'C:\\Users\\GS-1436\\PycharmProjects\\inductproject\\snapp\\urls.py'> (None:None) >, <RegexURLPattern createinc ^create/$>], [<RegexURLResolver <module 'snapp.urls' from 'C:\\Users\\GS-1436\\PycharmProjects\\inductproject\\snapp\\urls.py'> (None:None) >, <RegexURLPattern createdinc ^createdinc/$>], [<RegexURLResolver <module 'snapp.urls' from 'C:\\Users\\GS-1436\\PycharmProjects\\inductproject\\snapp\\urls.py'> (None:None) >, <RegexURLPattern updateinc ^update/$>], [<RegexURLResolver <module 'snapp.urls' from 'C:\\Users\\GS-1436\\PycharmProjects\\inductproject\\snapp\\urls.py'> (None:None) >, <RegexURLPattern update_select ^update_select/(?P<number>[A-Za-z0-9_@./&+-]+)$>], [<RegexURLResolver <module 'snapp.urls' from 'C:\\Users\\GS-1436\\PycharmProjects\\inductproject\\snapp\\urls.py'> (None:None) >, <RegexURLPattern getUpdateDetail ^getUpdateDetail/$>], [<RegexURLResolver <module 'snapp.urls' from 'C:\\Users\\GS-1436\\PycharmProjects\\inductproject\\snapp\\urls.py'> (None:None) >, <RegexURLPattern deleteinc ^delete/$>], [<RegexURLResolver <module 'snapp.urls' from 'C:\\Users\\GS-1436\\PycharmProjects\\inductproject\\snapp\\urls.py'> (None:None) >, <RegexURLPattern delete_select ^delete_select/$>], [<RegexURLPattern login ^login/$>], [<RegexURLPattern logout ^logout/$>]]}

During handling of the above exception, another exception occurred:

Traceback (most recent call last):
  File "C:\Users\GS-1436\VE-1\lib\site-packages\django\template\base.py", line 885, in _resolve_lookup
    current = current[bit]
TypeError: 'RegexURLResolver' object is not subscriptable

During handling of the above exception, another exception occurred:

Traceback (most recent call last):
  File "C:\Users\GS-1436\VE-1\lib\site-packages\django\template\base.py", line 893, in _resolve_lookup
    current = getattr(current, bit)
AttributeError: 'RegexURLResolver' object has no attribute 'name'

During handling of the above exception, another exception occurred:

Traceback (most recent call last):
  File "C:\Users\GS-1436\VE-1\lib\site-packages\django\template\base.py", line 900, in _resolve_lookup
    current = current[int(bit)]
ValueError: invalid literal for int() with base 10: 'name'

During handling of the above exception, another exception occurred:

Traceback (most recent call last):
  File "C:\Users\GS-1436\VE-1\lib\site-packages\django\template\base.py", line 907, in _resolve_lookup
    (bit, current))  # missing attribute
django.template.base.VariableDoesNotExist: Failed lookup for key [name] in '<RegexURLResolver <RegexURLPattern list> (admin:admin) ^admin/>'
Not Found: /list/bgimg.jpg
"GET /list/bgimg.jpg HTTP/1.1" 404 4231
(0.001) 
            SELECT name, type FROM sqlite_master
            WHERE type in ('table', 'view') AND NOT name='sqlite_sequence'
            ORDER BY name; args=None
(0.000) SELECT "django_migrations"."app", "django_migrations"."name" FROM "django_migrations"; args=()
(0.001) SELECT "django_session"."session_key", "django_session"."session_data", "django_session"."expire_date" FROM "django_session" WHERE ("django_session"."session_key" = 'o6eyvii97s2jm9ym4ajtdtpv3v3vizs5' AND "django_session"."expire_date" > '2017-03-20 12:27:16.750104'); args=('o6eyvii97s2jm9ym4ajtdtpv3v3vizs5', '2017-03-20 12:27:16.750104')
(0.000) SELECT "auth_user"."id", "auth_user"."password", "auth_user"."last_login", "auth_user"."is_superuser", "auth_user"."username", "auth_user"."first_name", "auth_user"."last_name", "auth_user"."email", "auth_user"."is_staff", "auth_user"."is_active", "auth_user"."date_joined" FROM "auth_user" WHERE "auth_user"."id" = 1; args=(1,)
(0.001) SELECT "django_session"."session_key", "django_session"."session_data", "django_session"."expire_date" FROM "django_session" WHERE ("django_session"."session_key" = 'o6eyvii97s2jm9ym4ajtdtpv3v3vizs5' AND "django_session"."expire_date" > '2017-03-20 12:27:34.864915'); args=('o6eyvii97s2jm9ym4ajtdtpv3v3vizs5', '2017-03-20 12:27:34.864915')
(0.000) SELECT "auth_user"."id", "auth_user"."password", "auth_user"."last_login", "auth_user"."is_superuser", "auth_user"."username", "auth_user"."first_name", "auth_user"."last_name", "auth_user"."email", "auth_user"."is_staff", "auth_user"."is_active", "auth_user"."date_joined" FROM "auth_user" WHERE "auth_user"."id" = 1; args=(1,)
"GET / HTTP/1.1" 200 3330
Exception while resolving variable 'name' in template 'unknown'.
Traceback (most recent call last):
  File "C:\Users\GS-1436\VE-1\lib\site-packages\django\core\handlers\exception.py", line 42, in inner
    response = get_response(request)
  File "C:\Users\GS-1436\VE-1\lib\site-packages\django\core\handlers\base.py", line 172, in _get_response
    resolver_match = resolver.resolve(request.path_info)
  File "C:\Users\GS-1436\VE-1\lib\site-packages\django\urls\resolvers.py", line 300, in resolve
    raise Resolver404({'tried': tried, 'path': new_path})
django.urls.exceptions.Resolver404: {'path': 'bgimg.jpg', 'tried': [[<RegexURLResolver <RegexURLPattern list> (admin:admin) ^admin/>], [<RegexURLResolver <module 'snapp.urls' from 'C:\\Users\\GS-1436\\PycharmProjects\\inductproject\\snapp\\urls.py'> (None:None) >, <RegexURLPattern home ^$>], [<RegexURLResolver <module 'snapp.urls' from 'C:\\Users\\GS-1436\\PycharmProjects\\inductproject\\snapp\\urls.py'> (None:None) >, <RegexURLPattern homepage ^home/$>], [<RegexURLResolver <module 'snapp.urls' from 'C:\\Users\\GS-1436\\PycharmProjects\\inductproject\\snapp\\urls.py'> (None:None) >, <RegexURLPattern list ^list/$>], [<RegexURLResolver <module 'snapp.urls' from 'C:\\Users\\GS-1436\\PycharmProjects\\inductproject\\snapp\\urls.py'> (None:None) >, <RegexURLPattern incident_details ^incident_details/(?P<sys_id>[A-Za-z0-9_@./&+-]+)$>], [<RegexURLResolver <module 'snapp.urls' from 'C:\\Users\\GS-1436\\PycharmProjects\\inductproject\\snapp\\urls.py'> (None:None) >, <RegexURLPattern createinc ^create/$>], [<RegexURLResolver <module 'snapp.urls' from 'C:\\Users\\GS-1436\\PycharmProjects\\inductproject\\snapp\\urls.py'> (None:None) >, <RegexURLPattern createdinc ^createdinc/$>], [<RegexURLResolver <module 'snapp.urls' from 'C:\\Users\\GS-1436\\PycharmProjects\\inductproject\\snapp\\urls.py'> (None:None) >, <RegexURLPattern updateinc ^update/$>], [<RegexURLResolver <module 'snapp.urls' from 'C:\\Users\\GS-1436\\PycharmProjects\\inductproject\\snapp\\urls.py'> (None:None) >, <RegexURLPattern update_select ^update_select/(?P<number>[A-Za-z0-9_@./&+-]+)$>], [<RegexURLResolver <module 'snapp.urls' from 'C:\\Users\\GS-1436\\PycharmProjects\\inductproject\\snapp\\urls.py'> (None:None) >, <RegexURLPattern getUpdateDetail ^getUpdateDetail/$>], [<RegexURLResolver <module 'snapp.urls' from 'C:\\Users\\GS-1436\\PycharmProjects\\inductproject\\snapp\\urls.py'> (None:None) >, <RegexURLPattern deleteinc ^delete/$>], [<RegexURLResolver <module 'snapp.urls' from 'C:\\Users\\GS-1436\\PycharmProjects\\inductproject\\snapp\\urls.py'> (None:None) >, <RegexURLPattern delete_select ^delete_select/$>], [<RegexURLPattern login ^login/$>], [<RegexURLPattern logout ^logout/$>]]}

During handling of the above exception, another exception occurred:

Traceback (most recent call last):
  File "C:\Users\GS-1436\VE-1\lib\site-packages\django\template\base.py", line 885, in _resolve_lookup
    current = current[bit]
TypeError: 'RegexURLResolver' object is not subscriptable

During handling of the above exception, another exception occurred:

Traceback (most recent call last):
  File "C:\Users\GS-1436\VE-1\lib\site-packages\django\template\base.py", line 893, in _resolve_lookup
    current = getattr(current, bit)
AttributeError: 'RegexURLResolver' object has no attribute 'name'

During handling of the above exception, another exception occurred:

Traceback (most recent call last):
  File "C:\Users\GS-1436\VE-1\lib\site-packages\django\template\base.py", line 900, in _resolve_lookup
    current = current[int(bit)]
ValueError: invalid literal for int() with base 10: 'name'

During handling of the above exception, another exception occurred:

Traceback (most recent call last):
  File "C:\Users\GS-1436\VE-1\lib\site-packages\django\template\base.py", line 907, in _resolve_lookup
    (bit, current))  # missing attribute
django.template.base.VariableDoesNotExist: Failed lookup for key [name] in '<RegexURLResolver <RegexURLPattern list> (admin:admin) ^admin/>'
Not Found: /bgimg.jpg
"GET /bgimg.jpg HTTP/1.1" 404 4216
(0.000) SELECT "django_session"."session_key", "django_session"."session_data", "django_session"."expire_date" FROM "django_session" WHERE ("django_session"."session_key" = 'o6eyvii97s2jm9ym4ajtdtpv3v3vizs5' AND "django_session"."expire_date" > '2017-03-20 12:27:37.386167'); args=('o6eyvii97s2jm9ym4ajtdtpv3v3vizs5', '2017-03-20 12:27:37.386167')
(0.001) SELECT "auth_user"."id", "auth_user"."password", "auth_user"."last_login", "auth_user"."is_superuser", "auth_user"."username", "auth_user"."first_name", "auth_user"."last_name", "auth_user"."email", "auth_user"."is_staff", "auth_user"."is_active", "auth_user"."date_joined" FROM "auth_user" WHERE "auth_user"."id" = 1; args=(1,)
"GET /list/ HTTP/1.1" 200 1154
"GET /list/ HTTP/1.1" 200 30553
Exception while resolving variable 'name' in template 'unknown'.
Traceback (most recent call last):
  File "C:\Users\GS-1436\VE-1\lib\site-packages\django\core\handlers\exception.py", line 42, in inner
    response = get_response(request)
  File "C:\Users\GS-1436\VE-1\lib\site-packages\django\core\handlers\base.py", line 172, in _get_response
    resolver_match = resolver.resolve(request.path_info)
  File "C:\Users\GS-1436\VE-1\lib\site-packages\django\urls\resolvers.py", line 300, in resolve
    raise Resolver404({'tried': tried, 'path': new_path})
django.urls.exceptions.Resolver404: {'path': 'list/bgimg.jpg', 'tried': [[<RegexURLResolver <RegexURLPattern list> (admin:admin) ^admin/>], [<RegexURLResolver <module 'snapp.urls' from 'C:\\Users\\GS-1436\\PycharmProjects\\inductproject\\snapp\\urls.py'> (None:None) >, <RegexURLPattern home ^$>], [<RegexURLResolver <module 'snapp.urls' from 'C:\\Users\\GS-1436\\PycharmProjects\\inductproject\\snapp\\urls.py'> (None:None) >, <RegexURLPattern homepage ^home/$>], [<RegexURLResolver <module 'snapp.urls' from 'C:\\Users\\GS-1436\\PycharmProjects\\inductproject\\snapp\\urls.py'> (None:None) >, <RegexURLPattern list ^list/$>], [<RegexURLResolver <module 'snapp.urls' from 'C:\\Users\\GS-1436\\PycharmProjects\\inductproject\\snapp\\urls.py'> (None:None) >, <RegexURLPattern incident_details ^incident_details/(?P<sys_id>[A-Za-z0-9_@./&+-]+)$>], [<RegexURLResolver <module 'snapp.urls' from 'C:\\Users\\GS-1436\\PycharmProjects\\inductproject\\snapp\\urls.py'> (None:None) >, <RegexURLPattern createinc ^create/$>], [<RegexURLResolver <module 'snapp.urls' from 'C:\\Users\\GS-1436\\PycharmProjects\\inductproject\\snapp\\urls.py'> (None:None) >, <RegexURLPattern createdinc ^createdinc/$>], [<RegexURLResolver <module 'snapp.urls' from 'C:\\Users\\GS-1436\\PycharmProjects\\inductproject\\snapp\\urls.py'> (None:None) >, <RegexURLPattern updateinc ^update/$>], [<RegexURLResolver <module 'snapp.urls' from 'C:\\Users\\GS-1436\\PycharmProjects\\inductproject\\snapp\\urls.py'> (None:None) >, <RegexURLPattern update_select ^update_select/(?P<number>[A-Za-z0-9_@./&+-]+)$>], [<RegexURLResolver <module 'snapp.urls' from 'C:\\Users\\GS-1436\\PycharmProjects\\inductproject\\snapp\\urls.py'> (None:None) >, <RegexURLPattern getUpdateDetail ^getUpdateDetail/$>], [<RegexURLResolver <module 'snapp.urls' from 'C:\\Users\\GS-1436\\PycharmProjects\\inductproject\\snapp\\urls.py'> (None:None) >, <RegexURLPattern deleteinc ^delete/$>], [<RegexURLResolver <module 'snapp.urls' from 'C:\\Users\\GS-1436\\PycharmProjects\\inductproject\\snapp\\urls.py'> (None:None) >, <RegexURLPattern delete_select ^delete_select/$>], [<RegexURLPattern login ^login/$>], [<RegexURLPattern logout ^logout/$>]]}

During handling of the above exception, another exception occurred:

Traceback (most recent call last):
  File "C:\Users\GS-1436\VE-1\lib\site-packages\django\template\base.py", line 885, in _resolve_lookup
    current = current[bit]
TypeError: 'RegexURLResolver' object is not subscriptable

During handling of the above exception, another exception occurred:

Traceback (most recent call last):
  File "C:\Users\GS-1436\VE-1\lib\site-packages\django\template\base.py", line 893, in _resolve_lookup
    current = getattr(current, bit)
AttributeError: 'RegexURLResolver' object has no attribute 'name'

During handling of the above exception, another exception occurred:

Traceback (most recent call last):
  File "C:\Users\GS-1436\VE-1\lib\site-packages\django\template\base.py", line 900, in _resolve_lookup
    current = current[int(bit)]
ValueError: invalid literal for int() with base 10: 'name'

During handling of the above exception, another exception occurred:

Traceback (most recent call last):
  File "C:\Users\GS-1436\VE-1\lib\site-packages\django\template\base.py", line 907, in _resolve_lookup
    (bit, current))  # missing attribute
django.template.base.VariableDoesNotExist: Failed lookup for key [name] in '<RegexURLResolver <RegexURLPattern list> (admin:admin) ^admin/>'
Not Found: /list/bgimg.jpg
"GET /list/bgimg.jpg HTTP/1.1" 404 4231
